<mujoco model="MUSASHILARM">
    <compiler angle="radian" meshdir="MUSASHILARM_meshes/"/>
    <option collision="predefined" integrator="RK4"/>
    <size njmax="1000" nconmax="1000" />
    <default>
        <joint type="hinge" />
        <site rgba=".8 .6 .4 1"/>
    </default>
    <asset>
        <mesh name="LARM_SCAPULA_LINK_mesh" file="LARM_SCAPULA_LINK_mesh.stl" />
        <mesh name="LARM_HUMERUS_DUMMY1_LINK_mesh" file="LARM_HUMERUS_DUMMY1_LINK_mesh.stl" />
        <mesh name="LARM_HUMERUS_DUMMY2_LINK_mesh" file="LARM_HUMERUS_DUMMY2_LINK_mesh.stl"/>
        <mesh name="LARM_HUMERUS_LINK_mesh" file="LARM_HUMERUS_LINK_mesh.stl" />
        <mesh name="LARM_FOREARM_DUMMY1_LINK_mesh" file="LARM_FOREARM_DUMMY1_LINK_mesh.stl" />
        <mesh name="LARM_FOREARM_LINK_mesh" file="LARM_FOREARM_LINK_mesh.stl" />
        <mesh name="LARM_HAND_DUMMY1_LINK_mesh" file="LARM_HAND_DUMMY1_LINK_mesh.stl" />
        <mesh name="LARM_HAND_LINK_mesh" file="LARM_HAND_LINK_mesh.stl" />
        <mesh name="LARM_INDEX3_LINK_mesh" file="LARM_INDEX3_LINK_mesh.stl" />
        <mesh name="LARM_INDEX2_LINK_mesh" file="LARM_INDEX2_LINK_mesh.stl" />
        <mesh name="LARM_INDEX1_LINK_mesh" file="LARM_INDEX1_LINK_mesh.stl" />
        <mesh name="LARM_LITTLE3_LINK_mesh" file="LARM_LITTLE3_LINK_mesh.stl" />
        <mesh name="LARM_LITTLE2_LINK_mesh" file="LARM_LITTLE2_LINK_mesh.stl" />
        <mesh name="LARM_LITTLE1_LINK_mesh" file="LARM_LITTLE1_LINK_mesh.stl" />
        <mesh name="LARM_MIDDLE3_LINK_mesh" file="LARM_MIDDLE3_LINK_mesh.stl" />
        <mesh name="LARM_MIDDLE2_LINK_mesh" file="LARM_MIDDLE2_LINK_mesh.stl" />
        <mesh name="LARM_MIDDLE1_LINK_mesh" file="LARM_MIDDLE1_LINK_mesh.stl" />
        <mesh name="LARM_RING3_LINK_mesh" file="LARM_RING3_LINK_mesh.stl" />
        <mesh name="LARM_RING2_LINK_mesh" file="LARM_RING2_LINK_mesh.stl" />
        <mesh name="LARM_RING1_LINK_mesh" file="LARM_RING1_LINK_mesh.stl" />
        <mesh name="LARM_THUMB4_LINK_mesh" file="LARM_THUMB4_LINK_mesh.stl" />
        <mesh name="LARM_THUMB3_LINK_mesh" file="LARM_THUMB3_LINK_mesh.stl" />
        <mesh name="LARM_THUMB2_LINK_mesh" file="LARM_THUMB2_LINK_mesh.stl" />
        <mesh name="LARM_THUMB1_LINK_mesh" file="LARM_THUMB1_LINK_mesh.stl" />
    </asset>
    <worldbody>
        <geom type="mesh" mesh="LARM_SCAPULA_LINK_mesh" />
        <geom name="LARM_SCAPULA_LINK" type="cylinder" fromto="0 0 0 0 0.28 0" size="0.015" rgba=".8 .6 .4 0"/>
            <body name="LARM_HUMERUS_DUMMY1_LINK" pos="0 0.193 0">
            <!--<body name="LARM_HUMERUS_DUMMY1_LINK" pos="0 0.193 0">-->
            <inertial pos="0 0 0" quat="0.820473 0.339851 -0.17592 0.424708" mass="0.001" diaginertia="0.001 0.001 0.001" />
            <joint name="LARM_SHOULDER_JOINT_P" pos="0 0 0" axis="0 1 0" limited="true" range="-2.0944 0.785399" damping="0.2" type="hinge"/>
            <geom pos="0 0.193 0" type="mesh" mesh="LARM_HUMERUS_DUMMY1_LINK_mesh" />
            <geom name="LARM_HUMERUS_DUMMY1_LINK" type="sphere" size="0.035" rgba=".8 .6 .4 0" pos="0 0.035 0"/>
            <body name="LARM_HUMERUS_DUMMY2_LINK" pos="0 0.039 0">
                <inertial pos="0 0 0" quat="0.820473 0.339851 -0.17592 0.424708" mass="0.001" diaginertia="0.001 0.001 0.001" />
                <joint name="LARM_SHOULDER_JOINT_R" pos="0 0 0" axis="1 0 0" limited="true" range="-0.523599 2.0944" damping="0.2" type="hinge"/>
                <geom pos="0 0.039 0" type="mesh" mesh="LARM_HUMERUS_DUMMY2_LINK_mesh" />
                <geom name="LARM_HUMERUS_DUMMY2_LINK" type="cylinder" fromto="0 0 0.04 0 0 -0.08" size="0.025" rgba=".8 .6 .4 0"/>
                <geom name="LARM_HUMERUS_DUMMY2_LINK_thin" type="cylinder" fromto="0 0 0.04 0 0 -0.08" size="0.015" rgba=".8 .6 .4 1"/>
                <body name="LARM_HUMERUS_LINK" pos="0 0 -0.073">
                    <inertial pos="0.024 0.0021 -0.135" quat="0.820473 0.339851 -0.17592 0.424708" mass="2.19" diaginertia="0.001 0.001 0.001" />
                    <joint name="LARM_SHOULDER_JOINT_Y" pos="0 0 0" axis="0 0 1" limited="true" range="-1.5708 1.5708" damping="0.2" type="hinge"/>
                    <geom pos="0 0 -0.073" type="mesh" mesh="LARM_HUMERUS_LINK_mesh" />
                    <geom name="LARM_HUMERUS_LINK" type="cylinder" size="0.05" fromto="-0.01 0 -0.02 -0.01 0 -0.15" rgba=".8 .6 .4 0"/>
                    <body name="LARM_FOREARM_DUMMY1_LINK" pos="0.004 0 -0.231">
                        <inertial pos="-0.008065 0 -0.146065" quat="0.820473 0.339851 -0.17592 0.424708" mass="0.72" diaginertia="0.001 0.001 0.001" />
                        <joint name="LARM_ELBOW_JOINT_P" pos="0 0 0" axis="0 1 0" limited="true" range="-2.3562 0" damping="0.2" type="hinge"/>
                        <geom pos="0.004 0 -0.231" type="mesh" mesh="LARM_FOREARM_DUMMY1_LINK_mesh" />
                        <geom name="LARM_FOREARM_DUMMY1_LINK" type="sphere" size="0.035" rgba=".8 .6 .4 0" pos="0 0 0"/>
                        <geom name="LARM_FOREARM_DUMMY1_LINK_cylinder" type="cylinder" size="0.035" rgba=".8 .6 .4 0" fromto="0 0 0.03 0 0 -0.05"/>
                        <geom name="LARM_FOREARM_DUMMY1_LINK_cylinder_thin" type="cylinder" size="0.025" rgba=".8 .6 .4 0" fromto="0 0 0 0 0 -0.05"/>
                        <geom name="LARM_FOREARM_DUMMY1_LINK_cylinder_thin_thin" type="cylinder" size="0.02" rgba=".8 .6 .4 0" fromto="0 0 0 0 0 -0.05"/>
                        <body name="LARM_FOREARM_LINK" pos="0 0 -0.04">
                            <inertial pos="-0.003285 0 -0.13898" quat="0.820473 0.339851 -0.17592 0.424708" mass="0.75" diaginertia="0.001 0.001 0.001" />
                            <joint name="LARM_ELBOW_JOINT_Y" pos="0 0 0" axis="0.104591 0 0.994515" limited="true" range="-1.5708 1.5708" damping="0.2" type="hinge"/>
                            <geom pos="0 0 -0.04" type="mesh" mesh="LARM_FOREARM_LINK_mesh" />
                            <body name="LARM_HAND_DUMMY1_LINK" pos="0 0 -0.191">
                                <inertial pos="0 0 0" quat="0.820473 0.339851 -0.17592 0.424708" mass="0.001" diaginertia="0.001 0.001 0.001" />
                                <joint name="LARM_WRIST_JOINT_P" pos="0 0 0" axis="0 1 0" limited="true" range="-0.7854 0.7854" damping="0.2" type="hinge"/>
                                <geom pos="0 0 -0.191" type="mesh" mesh="LARM_HAND_DUMMY1_LINK_mesh" />
                                <geom name="LARM_HAND_DUMMY1_LINK" type="sphere" size="0.035" rgba=".8 .6 .4 0" pos="0 0 0"/>
                                <body name="LARM_HAND_LINK" pos="0 0 0">
                                    <inertial pos="0.01125 0 -0.03" quat="0.820473 0.339851 -0.17592 0.424708" mass="0.192" diaginertia="0.001 0.001 0.001" />
                                    <joint name="LARM_WRIST_JOINT_R" pos="0 0 0" axis="1 0 0" limited="true" range="-1.309 1.309" damping="0.2" type="hinge"/>
                                    <geom type="mesh" mesh="LARM_HAND_LINK_mesh" />
                                    <geom name="ball_geom" rgba="0.8 0.6 0.6 1" type="cylinder" fromto="-0.1 0 0 0.1 0 0" size="0.028" density="2000" contype="2" conaffinity="1" />
                                    <site name="hand-end1" pos="0.0 0.0 0.0" size="0.005"/>
                                    <site name="hand-end2" pos="0.0 0.0 0.0" size="0.005"/>
                                    <body name="LARM_INDEX3_LINK" pos="0.0349544 -0.017 -0.100974">
                                        <inertial pos="0 0 0" quat="0.820473 0.339851 -0.17592 0.424708" mass="0.001" diaginertia="0.001 0.001 0.001" />
                                        <geom pos="0.0349544 -0.017 -0.100974" type="mesh" mesh="LARM_INDEX3_LINK_mesh" />
                                        <body name="LARM_INDEX2_LINK" pos="0.00348623 0 -0.0398478">
                                            <inertial pos="0 0 0" quat="0.820473 0.339851 -0.17592 0.424708" mass="0.001" diaginertia="0.001 0.001 0.001" />
                                            <geom pos="0.00348623 0 -0.0398478" type="mesh" mesh="LARM_INDEX2_LINK_mesh" />
                                            <body name="LARM_INDEX1_LINK" pos="0.00261467 0 -0.0298858">
                                                <inertial pos="0 0 0" quat="0.820473 0.339851 -0.17592 0.424708" mass="0.001" diaginertia="0.001 0.001 0.001" />
                                                <geom pos="0.00261467 0 -0.0298858" type="mesh" mesh="LARM_INDEX1_LINK_mesh" />
                                            </body>
                                        </body>
                                    </body>
                                    <body name="LARM_LITTLE3_LINK" pos="-0.0273876 -0.017 -0.098252">
                                        <inertial pos="0 0 0" quat="0.820473 0.339851 -0.17592 0.424708" mass="0.001" diaginertia="0.001 0.001 0.001" />
                                        <geom pos="-0.0273876 -0.017 -0.098252" type="mesh" mesh="LARM_LITTLE3_LINK_mesh" />
                                        <body name="LARM_LITTLE2_LINK" pos="-0.00520945 0 -0.0295442">
                                            <inertial pos="0 0 0" quat="0.820473 0.339851 -0.17592 0.424708" mass="0.001" diaginertia="0.001 0.001 0.001" />
                                            <geom pos="-0.00520945 0 -0.0295442" type="mesh" mesh="LARM_LITTLE2_LINK_mesh" />
                                            <body name="LARM_LITTLE1_LINK" pos="-0.00520945 0 -0.0295442">
                                                <inertial pos="0 0 0" quat="0.820473 0.339851 -0.17592 0.424708" mass="0.001" diaginertia="0.001 0.001 0.001" />
                                                <geom pos="-0.00520945 0 -0.0295442" type="mesh" mesh="LARM_LITTLE1_LINK_mesh" />
                                            </body>
                                        </body>
                                    </body>
                                    <body name="LARM_MIDDLE3_LINK" pos="0.0141209 -0.017 -0.101883">
                                        <inertial pos="0 0 0" quat="0.820473 0.339851 -0.17592 0.424708" mass="0.001" diaginertia="0.001 0.001 0.001" />
                                        <geom pos="0.0141209 -0.017 -0.101883" type="mesh" mesh="LARM_MIDDLE3_LINK_mesh" />
                                        <body name="LARM_MIDDLE2_LINK" pos="0 0 -0.04">
                                            <inertial pos="0 0 0" quat="0.820473 0.339851 -0.17592 0.424708" mass="0.001" diaginertia="0.001 0.001 0.001" />
                                            <geom pos="0 0 -0.04" type="mesh" mesh="LARM_MIDDLE2_LINK_mesh" />
                                            <body name="LARM_MIDDLE1_LINK" pos="0 0 -0.03">
                                                <inertial pos="0 0 0" quat="0.820473 0.339851 -0.17592 0.424708" mass="0.001" diaginertia="0.001 0.001 0.001" />
                                                <geom pos="0 0 -0.03" type="mesh" mesh="LARM_MIDDLE1_LINK_mesh" />
                                            </body>
                                        </body>
                                    </body>
                                    <body name="LARM_RING3_LINK" pos="-0.00671263 -0.017 -0.100974">
                                        <inertial pos="0 0 0" quat="0.820473 0.339851 -0.17592 0.424708" mass="0.001" diaginertia="0.001 0.001 0.001" />
                                        <geom pos="-0.00671263 -0.017 -0.100974" type="mesh" mesh="LARM_RING3_LINK_mesh" />
                                        <body name="LARM_RING2_LINK" pos="-0.00348623 0 -0.0398478">
                                            <inertial pos="0 0 0" quat="0.820473 0.339851 -0.17592 0.424708" mass="0.001" diaginertia="0.001 0.001 0.001" />
                                            <geom pos="-0.00348623 0 -0.0398478" type="mesh" mesh="LARM_RING2_LINK_mesh" />
                                            <body name="LARM_RING1_LINK" pos="-0.00261467 0 -0.0298858">
                                                <inertial pos="0 0 0" quat="0.820473 0.339851 -0.17592 0.424708" mass="0.001" diaginertia="0.001 0.001 0.001" />
                                                <geom pos="-0.00261467 0 -0.0298858" type="mesh" mesh="LARM_RING1_LINK_mesh" />
                                            </body>
                                        </body>
                                    </body>
                                    <body name="LARM_THUMB4_LINK" pos="0.0299678 -0.006 -0.0497134">
                                        <inertial pos="0 0 0" quat="0.820473 0.339851 -0.17592 0.424708" mass="0.001" diaginertia="0.001 0.001 0.001" />
                                        <geom pos="0.0299678 -0.006 -0.0497134" type="mesh" mesh="LARM_THUMB4_LINK_mesh" />
                                        <body name="LARM_THUMB3_LINK" pos="0 0 0">
                                            <inertial pos="0 0 0" quat="0.820473 0.339851 -0.17592 0.424708" mass="0.001" diaginertia="0.001 0.001 0.001" />
                                            <geom type="mesh" mesh="LARM_THUMB3_LINK_mesh" />
                                            <body name="LARM_THUMB2_LINK" pos="0.0360228 -0.011 -0.0109274">
                                                <inertial pos="0 0 0" quat="0.820473 0.339851 -0.17592 0.424708" mass="0.001" diaginertia="0.001 0.001 0.001" />
                                                <geom pos="0.0360228 -0.011 -0.0109274" type="mesh" mesh="LARM_THUMB2_LINK_mesh" />
                                                <body name="LARM_THUMB1_LINK" pos="0.0245746 0 -0.0172073">
                                                    <inertial pos="0 0 0" quat="0.820473 0.339851 -0.17592 0.424708" mass="0.001" diaginertia="0.001 0.001 0.001" />
                                                    <geom pos="0.0245746 0 -0.0172073" type="mesh" mesh="LARM_THUMB1_LINK_mesh" />
                                                </body>
                                            </body>
                                        </body>
                                    </body>
                                </body>
                            </body>
                        </body>
                    </body>
                </body>
            </body>
        </body>

        <body name="g1" pos="0.334 0.3 -0.47" axisangle="0 1 0 0.05">
            <geom name="g1" rgba="0.2 0.2 0.2 1" type="box" size="0.003 0.01 0.05" contype="1" conaffinity="1" />
        </body>

        <body name="g2" pos="0.266 0.3 -0.47" axisangle="0 1 0 -0.05">
            <geom name="g2" rgba="0.2 0.2 0.2 1" type="box" size="0.003 0.01 0.05" contype="1" conaffinity="1" />
        </body>

        <body name="g3" pos="0.3 0.334 -0.47" axisangle="1 0 0 -0.05">
            <geom name="g3" rgba="0.2 0.2 0.2 1" type="box" size="0.01 0.003 0.05" contype="1" conaffinity="1" />
        </body>

        <body name="g4" pos="0.3 0.266 -0.47" axisangle="1 0 0 0.05">
            <geom name="g4" rgba="0.2 0.2 0.2 1" type="box" size="0.01 0.003 0.05" contype="1" conaffinity="1" />
        </body>

        <body name="fl" pos="0.3 0.3 -0.55">
            <geom name="fl" rgba="0.2 0.2 0.2 1" type="box" size="0.2 0.2 0.05" contype="1" conaffinity="1" />
        </body>

        <body name="w1" pos="0.516 0.3 -0.45">
            <geom name="w1" rgba="0.2 0.2 0.2 1" type="box" size="0.183 0.3 0.05" contype="1" conaffinity="1" />
        </body>

        <body name="w2" pos="0.084 0.3 -0.45">
            <geom name="w2" rgba="0.2 0.2 0.2 1" type="box" size="0.183 0.3 0.05" contype="1" conaffinity="1" />
        </body>

        <body name="w3" pos="0.3 0.516 -0.45">
            <geom name="w3" rgba="0.2 0.2 0.2 1" type="box" size="0.032 0.183 0.05" contype="1" conaffinity="1" />
        </body>
        
        <body name="w4" pos="0.3 0.084 -0.45">
            <geom name="w4" rgba="0.2 0.2 0.2 1" type="box" size="0.032 0.183 0.05" contype="1" conaffinity="1" />
        </body>

    </worldbody>
    <!--
    <tendon>
        <spatial name="wire-forearm-1l" width="0.003" rgba=".4 .6 .4 1">
            <site site="pull-forearm-1"/>
            <geom geom="LARM_HAND_DUMMY1_LINK"/>
            <site site="pulled-forearm-1"/>
        </spatial>
        <spatial name="wire-forearm-2l" width="0.003" rgba=".4 .6 .4 1">
            <site site="pull-forearm-2"/>
            <geom geom="LARM_HAND_DUMMY1_LINK"/>
            <site site="pulled-forearm-2"/>
        </spatial>
        <spatial name="wire-forearm-3l" width="0.003" rgba=".4 .6 .4 1">
            <site site="pull-forearm-3"/>
            <geom geom="LARM_HAND_DUMMY1_LINK"/>
            <site site="via-forearm-3-1"/>
            <site site="via-forearm-3-2"/>
            <site site="via-forearm-3-3"/>
            <site site="via-forearm-3-4"/>
            <site site="via-forearm-3-5"/>
            <site site="via-forearm-3-6"/>
            <site site="pulled-forearm-3"/>
        </spatial>
        <spatial name="wire-forearm-4l" width="0.003" rgba=".4 .6 .4 1">
            <site site="pull-forearm-4"/>
            <geom geom="LARM_HAND_DUMMY1_LINK"/>
            <site site="via-forearm-4-1"/>
            <site site="via-forearm-4-2"/>
            <site site="pulled-forearm-4"/>
        </spatial>
        <spatial name="wire-forearm-5l" width="0.003" rgba=".4 .6 .4 1">
            <site site="pull-forearm-5"/>
            <geom geom="LARM_HAND_DUMMY1_LINK"/>
            <site site="via-forearm-5-1"/>
            <site site="via-forearm-5-2"/>
            <site site="via-forearm-5-3"/>
            <site site="via-forearm-5-4"/>
            <site site="via-forearm-5-5"/>
            <site site="via-forearm-5-6"/>
            <site site="pulled-forearm-5"/>
        </spatial>
        <spatial name="wire-forearm-6l" width="0.003" rgba=".4 .6 .4 1">
            <site site="pull-forearm-6"/>
            <geom geom="LARM_HAND_DUMMY1_LINK"/>
            <site site="via-forearm-6-1"/>
            <site site="via-forearm-6-2"/>
            <site site="via-forearm-6-3"/>
            <site site="via-forearm-6-4"/>
            <site site="via-forearm-6-5"/>
            <site site="via-forearm-6-6"/>
            <site site="pulled-forearm-6"/>
        </spatial>
        <spatial name="wire-forearm-7l" width="0.003" rgba=".4 .6 .4 1">
            <site site="pull-forearm-7"/>
            <geom geom="LARM_HAND_DUMMY1_LINK"/>
            <site site="pulled-forearm-7"/>
        </spatial>
        <spatial name="wire-forearm-8l" width="0.003" rgba=".4 .6 .4 1">
            <site site="pull-forearm-8"/>
            <geom geom="LARM_HAND_DUMMY1_LINK"/>
            <site site="pulled-forearm-8"/>
        </spatial>
        <spatial name="wire-humerus-1l" width="0.005" rgba=".4 .6 .4 1">
            <site site="pull-humerus-1"/>
            <site site="via-humerus-1-1"/>
            <geom geom="LARM_FOREARM_DUMMY1_LINK"/>
            <site site="via-humerus-1-2"/>
            <geom geom="LARM_FOREARM_DUMMY1_LINK_cylinder_thin_thin" sidesite="larm-forearm-outer"/>
            <site site="via-humerus-1-3"/>
            <geom geom="LARM_FOREARM_DUMMY1_LINK_cylinder_thin_thin" sidesite="larm-forearm-outer"/>
            <site site="via-humerus-1-4"/>
            <geom geom="LARM_FOREARM_DUMMY1_LINK"/>
            <site site="via-humerus-1-5"/>
            <site site="pulled-humerus-1"/>
        </spatial>
        <spatial name="wire-humerus-2l" width="0.003" rgba=".4 .6 .4 1">
            <site site="pull-humerus-2"/>
            <geom geom="LARM_HUMERUS_DUMMY1_LINK"/>
            <site site="via-humerus-2-1"/>
            <geom geom="LARM_HUMERUS_DUMMY1_LINK"/>
            <site site="pulled-humerus-2"/>
        </spatial>
        <spatial name="wire-humerus-3l" width="0.003" rgba=".4 .6 .4 1">
            <site site="pull-humerus-3"/>
            <site site="via-humerus-3-1"/>
            <geom geom="LARM_FOREARM_DUMMY1_LINK"/>
            <site site="via-humerus-3-2"/>
            <geom geom="LARM_FOREARM_DUMMY1_LINK_cylinder_thin_thin" sidesite="larm-forearm-insider"/>
            <site site="via-humerus-3-3"/>
            <geom geom="LARM_FOREARM_DUMMY1_LINK_cylinder_thin_thin" sidesite="larm-forearm-insider"/>
            <site site="via-humerus-3-4"/>
            <geom geom="LARM_FOREARM_DUMMY1_LINK"/>
            <site site="via-humerus-3-5"/>
            <site site="pulled-humerus-3"/>
        </spatial>
        <spatial name="wire-humerus-4l" width="0.003" rgba=".4 .6 .4 1">
            <site site="pull-humerus-4"/>
            <geom geom="LARM_FOREARM_DUMMY1_LINK_cylinder_thin" sidesite="larm-forearm-front"/>
            <site site="via-humerus-4-1"/>
            <geom geom="LARM_FOREARM_DUMMY1_LINK_cylinder_thin" sidesite="larm-forearm-front"/>
            <site site="pulled-humerus-4"/>
        </spatial>
        <spatial name="wire-humerus-5l" width="0.003" rgba=".4 .6 .4 1">
            <site site="pull-humerus-5"/>
            <geom geom="LARM_FOREARM_DUMMY1_LINK_cylinder" sidesite="larm-forearm-front"/>
            <site site="via-humerus-5-1"/>
            <geom geom="LARM_FOREARM_DUMMY1_LINK_cylinder" sidesite="larm-forearm-front"/>
            <site site="pulled-humerus-5"/>
        </spatial>
        <spatial name="wire-scapula-1l" width="0.003" rgba=".4 .6 .4 1">
            <site site="pull-scapula-1"/>
            <site site="via-scapula-1-1"/>
            <geom geom="LARM_HUMERUS_DUMMY1_LINK"/>
            <site site="via-scapula-1-2"/>
        </spatial>
        <spatial name="wire-scapula-2l" width="0.003" rgba=".4 .6 .4 1">
            <site site="pull-scapula-2"/>
            <site site="via-scapula-2-1"/>
            <geom geom="LARM_HUMERUS_DUMMY1_LINK" sidesite="larm-humerus-linkouter"/>
            <site site="via-scapula-2-2"/>
            <geom geom="LARM_HUMERUS_DUMMY2_LINK" sidesite="larm-humerus-linkouter"/>
            <site site="pulled-scapula-2"/>
        </spatial>
        <spatial name="wire-scapula-3l" width="0.003" rgba=".4 .6 .4 1">
            <site site="pull-scapula-3"/>
            <site site="via-scapula-3-1"/>
            <geom geom="LARM_HUMERUS_DUMMY1_LINK"/>
            <site site="via-scapula-3-2"/>
            <geom geom="LARM_HUMERUS_DUMMY1_LINK" />
            <site site="pulled-scapula-3"/>
        </spatial>
        <spatial name="wire-scapula-4l" width="0.003" rgba=".4 .6 .4 1">
            <site site="pull-scapula-4"/>
            <geom geom="LARM_HUMERUS_DUMMY2_LINK_thin" sidesite="larm-humerus-linkinsider"/>
            <site site="via-scapula-4-1"/>
            <geom geom="LARM_HUMERUS_DUMMY2_LINK_thin"/>
            <site site="via-scapula-4-2"/>
            <geom geom="LARM_HUMERUS_DUMMY1_LINK"/>
            <site site="pulled-scapula-4"/>
        </spatial>
        <spatial name="wire-scapula-5l" width="0.003" rgba=".4 .6 .4 1">
            <site site="pull-scapula-5"/>
            <geom geom="LARM_HUMERUS_DUMMY2_LINK_thin"/>
            <site site="via-scapula-5-1"/>
            <geom geom="LARM_HUMERUS_DUMMY2_LINK_thin"/>
            <site site="via-scapula-5-2"/>
            <geom geom="LARM_HUMERUS_DUMMY1_LINK"/>
            <site site="pulled-scapula-5"/>
        </spatial>
    </tendon>
    -->
    <actuator>
        <!--
        <muscle name="wire-forearm-1l" tendon="wire-forearm-1l"/>
        <muscle name="wire-forearm-2l" tendon="wire-forearm-2l"/>
        <muscle name="wire-forearm-3l" tendon="wire-forearm-3l"/>
        <muscle name="wire-forearm-4l" tendon="wire-forearm-4l"/>
        <muscle name="wire-forearm-5l" tendon="wire-forearm-5l"/>
        <muscle name="wire-forearm-6l" tendon="wire-forearm-6l"/>
        <muscle name="wire-forearm-7l" tendon="wire-forearm-7l"/>
        <muscle name="wire-forearm-8l" tendon="wire-forearm-8l"/>
        <muscle name="wire-humerus-1l" tendon="wire-humerus-1l"/>
        <muscle name="wire-humerus-2l" tendon="wire-humerus-2l"/>
        <muscle name="wire-humerus-3l" tendon="wire-humerus-3l"/>
        <muscle name="wire-humerus-4l" tendon="wire-humerus-4l"/>
        <muscle name="wire-humerus-5l" tendon="wire-humerus-5l"/>
        <muscle name="wire-scapula-1l" tendon="wire-scapula-1l"/>
        <muscle name="wire-scapula-2l" tendon="wire-scapula-2l"/>
        <muscle name="wire-scapula-3l" tendon="wire-scapula-3l"/>
        <muscle name="wire-scapula-4l" tendon="wire-scapula-4l"/>
        <muscle name="wire-scapula-5l" tendon="wire-scapula-5l"/>
        -->
        <motor joint="LARM_SHOULDER_JOINT_P" ctrlrange="-100.0 100.0" ctrllimited="true"/>
        <motor joint="LARM_SHOULDER_JOINT_R" ctrlrange="-100.0 100.0" ctrllimited="true"/>
        <motor joint="LARM_SHOULDER_JOINT_Y" ctrlrange="-100.0 100.0" ctrllimited="true"/>
        <motor joint="LARM_ELBOW_JOINT_P" ctrlrange="-100.0 100.0" ctrllimited="true"/>
        <motor joint="LARM_ELBOW_JOINT_Y" ctrlrange="-100.0 100.0" ctrllimited="true"/>
        <motor joint="LARM_WRIST_JOINT_P" ctrlrange="-100.0 100.0" ctrllimited="true"/>
        <motor joint="LARM_WRIST_JOINT_R" ctrlrange="-100.0 100.0" ctrllimited="true"/>
    </actuator>
</mujoco>
