<mujoco model="MUSASHILARM">
    <compiler angle="radian" meshdir="MUSASHILARM_meshes/"/>
    <option collision="predefined" integrator="RK4"/>
    <size njmax="1000" nconmax="1000" />
    <default>
        <joint type="hinge" />
        <site rgba=".8 .6 .4 1"/>
    </default>
    <asset>
        <mesh name="LARM_SCAPULA_LINK_mesh" file="LARM_SCAPULA_LINK_mesh.stl" />
        <mesh name="LARM_HUMERUS_DUMMY1_LINK_mesh" file="LARM_HUMERUS_DUMMY1_LINK_mesh.stl" />
        <mesh name="LARM_HUMERUS_DUMMY2_LINK_mesh" file="LARM_HUMERUS_DUMMY2_LINK_mesh.stl"/>
        <mesh name="LARM_HUMERUS_LINK_mesh" file="LARM_HUMERUS_LINK_mesh.stl" />
        <mesh name="LARM_FOREARM_DUMMY1_LINK_mesh" file="LARM_FOREARM_DUMMY1_LINK_mesh.stl" />
        <mesh name="LARM_FOREARM_LINK_mesh" file="LARM_FOREARM_LINK_mesh.stl" />
        <mesh name="LARM_HAND_DUMMY1_LINK_mesh" file="LARM_HAND_DUMMY1_LINK_mesh.stl" />
        <mesh name="LARM_HAND_LINK_mesh" file="LARM_HAND_LINK_mesh.stl" />
        <mesh name="LARM_INDEX3_LINK_mesh" file="LARM_INDEX3_LINK_mesh.stl" />
        <mesh name="LARM_INDEX2_LINK_mesh" file="LARM_INDEX2_LINK_mesh.stl" />
        <mesh name="LARM_INDEX1_LINK_mesh" file="LARM_INDEX1_LINK_mesh.stl" />
        <mesh name="LARM_LITTLE3_LINK_mesh" file="LARM_LITTLE3_LINK_mesh.stl" />
        <mesh name="LARM_LITTLE2_LINK_mesh" file="LARM_LITTLE2_LINK_mesh.stl" />
        <mesh name="LARM_LITTLE1_LINK_mesh" file="LARM_LITTLE1_LINK_mesh.stl" />
        <mesh name="LARM_MIDDLE3_LINK_mesh" file="LARM_MIDDLE3_LINK_mesh.stl" />
        <mesh name="LARM_MIDDLE2_LINK_mesh" file="LARM_MIDDLE2_LINK_mesh.stl" />
        <mesh name="LARM_MIDDLE1_LINK_mesh" file="LARM_MIDDLE1_LINK_mesh.stl" />
        <mesh name="LARM_RING3_LINK_mesh" file="LARM_RING3_LINK_mesh.stl" />
        <mesh name="LARM_RING2_LINK_mesh" file="LARM_RING2_LINK_mesh.stl" />
        <mesh name="LARM_RING1_LINK_mesh" file="LARM_RING1_LINK_mesh.stl" />
        <mesh name="LARM_THUMB4_LINK_mesh" file="LARM_THUMB4_LINK_mesh.stl" />
        <mesh name="LARM_THUMB3_LINK_mesh" file="LARM_THUMB3_LINK_mesh.stl" />
        <mesh name="LARM_THUMB2_LINK_mesh" file="LARM_THUMB2_LINK_mesh.stl" />
        <mesh name="LARM_THUMB1_LINK_mesh" file="LARM_THUMB1_LINK_mesh.stl" />
    </asset>
    <worldbody>
        <geom type="mesh" mesh="LARM_SCAPULA_LINK_mesh" />
        <geom name="LARM_SCAPULA_LINK" type="cylinder" fromto="0 0 0 0 0.28 0" size="0.015" rgba=".8 .6 .4 0"/>
        <site name="via-humerus-2-1" pos="-0.0474700774129066 0.186685854122563 0.021395284707451497" size="0.005"/>
        <site name="pull-scapula-5" pos="0.0305 0.1565 -0.0238" size="0.005"/>
        <site name="pulled-scapula-4" pos="-0.0475000000028617 0.210499978929992 0.058984313483563706" size="0.005"/>
        <site name="pull-scapula-4" pos="-0.0305 0.1565 -0.0238" size="0.005"/>
        <site name="pulled-scapula-3" pos="0.0474999999971382 0.2225 0.0589999999999304" size="0.005"/>
        <site name="via-scapula-3-1" pos="0.027999999997138498 0.253802247634027 0.0526875836447638" size="0.005"/>
        <site name="pull-scapula-3" pos="0.0305 0.1565 0.0518" size="0.005"/>
        <site name="pulled-scapula-2" pos="0.047499999997138304 0.234499978929954 0.0589843134838235" size="0.005"/>
        <site name="pulled-scapula-5" pos="0.0474999999971382 0.210499978929992 0.0589843134838234" size="0.005"/>
        <site name="via-scapula-2-1" pos="0.0 0.253802247634027 0.0526875836447638" size="0.005"/>
        <site name="pull-scapula-2" pos="4.2975126967743e-07 0.1565 0.053300980210225904" size="0.005"/>
        <site name="pulled-scapula-1" pos="-0.0475000000028093 0.2225 0.0589999999999304" size="0.005"/>
        <site name="via-scapula-1-1" pos="-0.028000000002858398 0.253802247634027 0.052687583644803" size="0.005"/>
        <site name="pull-scapula-1" pos="-0.0305 0.1565 0.0518" size="0.005"/>
        <site name="pulled-humerus-4" pos="0.047499999997138304 0.1665 0.0339999999999303" size="0.005"/>
            <body name="LARM_HUMERUS_DUMMY1_LINK" pos="0 0.193 0">
            <!--<body name="LARM_HUMERUS_DUMMY1_LINK" pos="0 0.193 0">-->
            <inertial pos="0 0 0" quat="0.820473 0.339851 -0.17592 0.424708" mass="0.001" diaginertia="0.001 0.001 0.001" />
            <joint name="LARM_SHOULDER_JOINT_P" pos="0 0 0" axis="0 1 0" limited="true" range="-2.0944 0.785399" damping="0.2" type="hinge"/>
            <geom pos="0 0.193 0" type="mesh" mesh="LARM_HUMERUS_DUMMY1_LINK_mesh" />
            <geom name="LARM_HUMERUS_DUMMY1_LINK" type="sphere" size="0.035" rgba=".8 .6 .4 0" pos="0 0.035 0"/>
            <site name="larm-humerus-side" pos="0 0.1 0" size="0.008" rgba=".7 0 0 1"/>
            <body name="LARM_HUMERUS_DUMMY2_LINK" pos="0 0.039 0">
                <inertial pos="0 0 0" quat="0.820473 0.339851 -0.17592 0.424708" mass="0.001" diaginertia="0.001 0.001 0.001" />
                <joint name="LARM_SHOULDER_JOINT_R" pos="0 0 0" axis="1 0 0" limited="true" range="-0.523599 2.0944" damping="0.2" type="hinge"/>
                <geom pos="0 0.039 0" type="mesh" mesh="LARM_HUMERUS_DUMMY2_LINK_mesh" />
                <geom name="LARM_HUMERUS_DUMMY2_LINK" type="cylinder" fromto="0 0 0.04 0 0 -0.08" size="0.025" rgba=".8 .6 .4 0"/>
                <geom name="LARM_HUMERUS_DUMMY2_LINK_thin" type="cylinder" fromto="0 0 0.04 0 0 -0.08" size="0.015" rgba=".8 .6 .4 1"/>
                <site name="via-scapula-4-2" pos="0 -0.025 -0.03231" size="0.005"/>
                <site name="via-scapula-5-2" pos="0 -0.025 -0.03231" size="0.005"/>
                <body name="LARM_HUMERUS_LINK" pos="0 0 -0.073">
                    <inertial pos="0.024 0.0021 -0.135" quat="0.820473 0.339851 -0.17592 0.424708" mass="2.19" diaginertia="0.001 0.001 0.001" />
                    <joint name="LARM_SHOULDER_JOINT_Y" pos="0 0 0" axis="0 0 1" limited="true" range="-1.5708 1.5708" damping="0.2" type="hinge"/>
                    <geom pos="0 0 -0.073" type="mesh" mesh="LARM_HUMERUS_LINK_mesh" />
                    <geom name="LARM_HUMERUS_LINK" type="cylinder" size="0.05" fromto="-0.01 0 -0.02 -0.01 0 -0.15" rgba=".8 .6 .4 0"/>
                    <site name="larm-humerus-linkouter" pos="0 0.06 -0.02" size="0.007" rgba="0.6 0 0 1"/>
                    <site name="larm-humerus-linkinsider" pos="0 -0.06 -0.02" size="0.007" rgba="0.6 0 0 1"/>
                    <site name="via-scapula-5-1" pos="-0.0105000000028576 -0.0185 -0.0165000000000006" size="0.005"/>
                    <site name="pull-humerus-3" pos="-0.0518 0.0305 -0.1415" size="0.005"/>
                    <site name="pulled-humerus-2" pos="-0.041000000002863204 0.00725598479111878 -0.022500000000007302" size="0.005"/>
                    <site name="pulled-humerus-3" pos="-0.041 0.0385 -0.1455" size="0.005"/>
                    <site name="pull-humerus-2" pos="-0.0533 0.0 -0.0268" size="0.005"/>
                    <site name="pulled-humerus-1" pos="-0.039 -0.0385 -0.1455" size="0.005"/>
                    <site name="pull-humerus-4" pos="0.0238 0.0305 -0.1415" size="0.005"/>
                    <site name="via-scapula-1-2" pos="0.010499999997091801 0.0179999999999999 -0.0165000000000018" size="0.005"/>
                    <site name="pull-humerus-1" pos="-0.0518 -0.0305 -0.1415" size="0.005"/>
                    <site name="via-scapula-4-1" pos="0.0175499999971425 -7.4353349635566e-17 -0.0165000000000006" size="0.005"/>
                    <site name="via-scapula-3-2" pos="0.010499999997091801 -0.0185 -0.0165000000000006" size="0.005"/>
                    <site name="via-scapula-2-2" pos="-0.0290000000028618 0.012000000000003602 -0.0195000000000006" size="0.005"/>
                    <site name="pull-humerus-5" pos="0.0238 -0.0305 -0.1415" size="0.005"/>
                    <site name="pulled-humerus-5" pos="0.012 -0.0375 -0.1455" size="0.005"/>
                    <body name="LARM_FOREARM_DUMMY1_LINK" pos="0.004 0 -0.231">
                        <inertial pos="-0.008065 0 -0.146065" quat="0.820473 0.339851 -0.17592 0.424708" mass="0.72" diaginertia="0.001 0.001 0.001" />
                        <joint name="LARM_ELBOW_JOINT_P" pos="0 0 0" axis="0 1 0" limited="true" range="-2.3562 0" damping="0.2" type="hinge"/>
                        <geom pos="0.004 0 -0.231" type="mesh" mesh="LARM_FOREARM_DUMMY1_LINK_mesh" />
                        <geom name="LARM_FOREARM_DUMMY1_LINK" type="sphere" size="0.035" rgba=".8 .6 .4 0" pos="0 0 0"/>
                        <geom name="LARM_FOREARM_DUMMY1_LINK_cylinder" type="cylinder" size="0.035" rgba=".8 .6 .4 0" fromto="0 0 0.03 0 0 -0.05"/>
                        <geom name="LARM_FOREARM_DUMMY1_LINK_cylinder_thin" type="cylinder" size="0.025" rgba=".8 .6 .4 0" fromto="0 0 0 0 0 -0.05"/>
                        <geom name="LARM_FOREARM_DUMMY1_LINK_cylinder_thin_thin" type="cylinder" size="0.02" rgba=".8 .6 .4 0" fromto="0 0 0 0 0 -0.05"/>
                        <site name="via-humerus-3-5" pos="-0.024 0.003 0.0272" size="0.005"/>
                        <site name="via-humerus-3-4" pos="-0.006 -0.0237 -0.0288" size="0.005"/>
                        <site name="via-humerus-3-2" pos="-0.006 -0.023 -0.0338" size="0.005"/>
                        <site name="via-humerus-3-1" pos="-0.027 -0.003 0.0232" size="0.005"/>
                        <site name="via-humerus-1-5" pos="-0.024 0.003 0.0272" size="0.005"/>
                        <site name="via-humerus-1-4" pos="-0.006 0.0233 -0.027800000000000002" size="0.005"/>
                        <site name="via-humerus-1-1" pos="-0.027 0.003 0.0232" size="0.005"/>
                        <site name="via-humerus-1-2" pos="-0.006 0.023 -0.0338" size="0.005"/>
                        <body name="LARM_FOREARM_LINK" pos="0 0 -0.04">
                            <inertial pos="-0.003285 0 -0.13898" quat="0.820473 0.339851 -0.17592 0.424708" mass="0.75" diaginertia="0.001 0.001 0.001" />
                            <joint name="LARM_ELBOW_JOINT_Y" pos="0 0 0" axis="0.104591 0 0.994515" limited="true" range="-1.5708 1.5708" damping="0.2" type="hinge"/>
                            <geom pos="0 0 -0.04" type="mesh" mesh="LARM_FOREARM_LINK_mesh" />
                            <site name="larm-forearm-front" pos="0.06 0 0" size="0.008" rgba=".7 0 0 1"/>
                            <site name="larm-forearm-back" pos="-0.06 0 0" size="0.008" rgba=".7 0 0 1"/>
                            <site name="larm-forearm-outer" pos="0 0.06 0" size="0.008" rgba=".7 0 0 1"/>
                            <site name="larm-forearm-insider" pos="0 -0.06 0" size="0.008" rgba=".7 0 0 1"/>
                            <site name="pull-forearm-1" pos="0.029999999997142 0.0239971203378614 -0.132999999999999" size="0.005"/>
                            <site name="via-humerus-5-1" pos="-0.0008 0.0395 -0.0108" size="0.005"/>
                            <site name="via-humerus-4-1" pos="0.0 -0.032 -0.0108" size="0.005"/>
                            <site name="via-humerus-3-3" pos="0.0272 -0.0056 -0.0108" size="0.005"/>
                            <site name="pull-forearm-8" pos="-0.00800000000285838 0.03 -0.132999999999999" size="0.005"/>
                            <site name="pull-forearm-7" pos="-0.024000000002858398 0.03 -0.132999999999999" size="0.005"/>
                            <site name="pull-forearm-6" pos="-0.0300000000028584 -0.008 -0.132999999999999" size="0.005"/>
                            <site name="pull-forearm-5" pos="-0.0300000000028584 -0.024 -0.132999999999999" size="0.005"/>
                            <site name="via-humerus-1-3" pos="0.0272 0.0044 -0.0108" size="0.005"/>
                            <site name="pull-forearm-3" pos="0.023999999997142002 -0.0300028796621386 -0.132999999999999" size="0.005"/>
                            <site name="pull-forearm-4" pos="0.00799999999714196 -0.0300028796621385 -0.132999999999999" size="0.005"/>
                            <site name="pull-forearm-2" pos="0.029999999997142 0.00799712033786145 -0.132999999999999" size="0.005"/>
                            <body name="LARM_HAND_DUMMY1_LINK" pos="0 0 -0.191">
                                <inertial pos="0 0 0" quat="0.820473 0.339851 -0.17592 0.424708" mass="0.001" diaginertia="0.001 0.001 0.001" />
                                <joint name="LARM_WRIST_JOINT_P" pos="0 0 0" axis="0 1 0" limited="true" range="-0.7854 0.7854" damping="0.2" type="hinge"/>
                                <geom pos="0 0 -0.191" type="mesh" mesh="LARM_HAND_DUMMY1_LINK_mesh" />
                                <geom name="LARM_HAND_DUMMY1_LINK" type="sphere" size="0.035" rgba=".8 .6 .4 0" pos="0 0 0"/>
                                <body name="LARM_HAND_LINK" pos="0 0 0">
                                    <inertial pos="0.01125 0 -0.03" quat="0.820473 0.339851 -0.17592 0.424708" mass="0.192" diaginertia="0.001 0.001 0.001" />
                                    <joint name="LARM_WRIST_JOINT_R" pos="0 0 0" axis="1 0 0" limited="true" range="-1.309 1.309" damping="0.2" type="hinge"/>
                                    <geom type="mesh" mesh="LARM_HAND_LINK_mesh" />
                                    <geom name="ball_geom" rgba="0.8 0.6 0.6 1" type="cylinder" fromto="-0.1 0 0 0.1 0 0" size="0.028" density="2000" contype="2" conaffinity="1" />
                                    <site name="via-forearm-3-2" pos="0.0340392403798027 -0.0224999999999991 -0.090513814669148" size="0.005"/>
                                    <site name="pulled-forearm-2" pos="0.0229999999992854 -0.022 -0.023" size="0.005"/>
                                    <site name="pulled-forearm-8" pos="0.0039999999992854 0.021 -0.078" size="0.005"/>
                                    <site name="via-forearm-3-1" pos="0.000999999999285406 -0.024 -0.038" size="0.005"/>
                                    <site name="via-forearm-4-1" pos="-0.0060000000007145995 -0.024 -0.038" size="0.005"/>
                                    <site name="pulled-forearm-1" pos="0.0249999999992854 0.011 -0.04" size="0.005"/>
                                    <site name="via-forearm-5-1" pos="-0.00800000000071459 -0.024 -0.038" size="0.005"/>
                                    <site name="pulled-forearm-7" pos="-0.0260000000007146 0.008 -0.04" size="0.005"/>
                                    <site name="via-forearm-5-2" pos="-0.0060000000007145995 -0.023 -0.057" size="0.005"/>
                                    <site name="via-forearm-6-1" pos="-0.0130000000007146 -0.024 -0.038" size="0.005"/>
                                    <site name="via-forearm-4-2" pos="0.0209999999992854 -0.023 -0.085" size="0.005"/>
                                    <site name="via-forearm-6-2" pos="-0.00579749783928461 -0.022499999999999302 -0.09051381466914811" size="0.005"/>
                                    <body name="LARM_INDEX3_LINK" pos="0.0349544 -0.017 -0.100974">
                                        <inertial pos="0 0 0" quat="0.820473 0.339851 -0.17592 0.424708" mass="0.001" diaginertia="0.001 0.001 0.001" />
                                        <joint name="LARM_INDEX3_JOINT_R" pos="0 0 0" axis="0.996195 0 0.0871557" limited="true" range="-1.5708 0" damping="0.2" type="hinge"/>
                                        <geom pos="0.0349544 -0.017 -0.100974" type="mesh" mesh="LARM_INDEX3_LINK_mesh" />
                                        <site name="via-forearm-3-3" pos="0.00100231672025112 -0.00599999999999955 -0.011456098027166399" size="0.005"/>
                                        <site name="via-forearm-3-4" pos="0.00265827583245663 -0.00599999999999955 -0.030383797290909603" size="0.005"/>
                                        <body name="LARM_INDEX2_LINK" pos="0.00348623 0 -0.0398478">
                                            <inertial pos="0 0 0" quat="0.820473 0.339851 -0.17592 0.424708" mass="0.001" diaginertia="0.001 0.001 0.001" />
                                            <joint name="LARM_INDEX2_JOINT_R" pos="0 0 0" axis="0.996195 0 0.0871557" limited="true" range="-1.5708 0" damping="0.2" />
                                            <geom pos="0.00348623 0 -0.0398478" type="mesh" mesh="LARM_INDEX2_LINK_mesh" />
                                            <site name="via-forearm-3-5" pos="0.00108947246299876 -0.00599999999999955 -0.0124522927252581" size="0.005"/>
                                            <site name="via-forearm-3-6" pos="0.00187387414772767 -0.00599999999999955 -0.0214180450080838" size="0.005"/>
                                            <body name="LARM_INDEX1_LINK" pos="0.00261467 0 -0.0298858">
                                                <inertial pos="0 0 0" quat="0.820473 0.339851 -0.17592 0.424708" mass="0.001" diaginertia="0.001 0.001 0.001" />
                                                <joint name="LARM_INDEX1_JOINT_R" pos="0 0 0" axis="0.996195 0 0.0871557" limited="true" range="-1.5708 0" damping="0.2" />
                                                <geom pos="0.00261467 0 -0.0298858" type="mesh" mesh="LARM_INDEX1_LINK_mesh" />
                                                <site name="pulled-forearm-3" pos="0.00144 -0.010 -0.01644" size="0.005"/>
                                            </body>
                                        </body>
                                    </body>
                                    <body name="LARM_LITTLE3_LINK" pos="-0.0273876 -0.017 -0.098252">
                                        <inertial pos="0 0 0" quat="0.820473 0.339851 -0.17592 0.424708" mass="0.001" diaginertia="0.001 0.001 0.001" />
                                        <joint name="LARM_LITTLE3_JOINT_R" pos="0 0 0" axis="0.984808 0 -0.173648" limited="true" range="-1.5708 0" damping="0.2" />
                                        <geom pos="-0.0273876 -0.017 -0.098252" type="mesh" mesh="LARM_LITTLE3_LINK_mesh" />
                                        <body name="LARM_LITTLE2_LINK" pos="-0.00520945 0 -0.0295442">
                                            <inertial pos="0 0 0" quat="0.820473 0.339851 -0.17592 0.424708" mass="0.001" diaginertia="0.001 0.001 0.001" />
                                            <joint name="LARM_LITTLE2_JOINT_R" pos="0 0 0" axis="0.984808 0 -0.173648" limited="true" range="-1.5708 0" damping="0.2" />
                                            <geom pos="-0.00520945 0 -0.0295442" type="mesh" mesh="LARM_LITTLE2_LINK_mesh" />
                                            <body name="LARM_LITTLE1_LINK" pos="-0.00520945 0 -0.0295442">
                                                <inertial pos="0 0 0" quat="0.820473 0.339851 -0.17592 0.424708" mass="0.001" diaginertia="0.001 0.001 0.001" />
                                                <joint name="LARM_LITTLE1_JOINT_R" pos="0 0 0" axis="0.984808 0 -0.173648" limited="true" range="-1.5708 0" damping="0.2" />
                                                <geom pos="-0.00520945 0 -0.0295442" type="mesh" mesh="LARM_LITTLE1_LINK_mesh" />
                                            </body>
                                        </body>
                                    </body>
                                    <body name="LARM_MIDDLE3_LINK" pos="0.0141209 -0.017 -0.101883">
                                        <inertial pos="0 0 0" quat="0.820473 0.339851 -0.17592 0.424708" mass="0.001" diaginertia="0.001 0.001 0.001" />
                                        <joint name="LARM_MIDDLE3_JOINT_R" pos="0 0 0" axis="1 0 0" limited="true" range="-1.5708 0" damping="0.2" />
                                        <geom pos="0.0141209 -0.017 -0.101883" type="mesh" mesh="LARM_MIDDLE3_LINK_mesh" />
                                        <body name="LARM_MIDDLE2_LINK" pos="0 0 -0.04">
                                            <inertial pos="0 0 0" quat="0.820473 0.339851 -0.17592 0.424708" mass="0.001" diaginertia="0.001 0.001 0.001" />
                                            <joint name="LARM_MIDDLE2_JOINT_R" pos="0 0 0" axis="1 0 0" limited="true" range="-1.5708 0" damping="0.2" />
                                            <geom pos="0 0 -0.04" type="mesh" mesh="LARM_MIDDLE2_LINK_mesh" />
                                            <body name="LARM_MIDDLE1_LINK" pos="0 0 -0.03">
                                                <inertial pos="0 0 0" quat="0.820473 0.339851 -0.17592 0.424708" mass="0.001" diaginertia="0.001 0.001 0.001" />
                                                <joint name="LARM_MIDDLE1_JOINT_R" pos="0 0 0" axis="1 0 0" limited="true" range="-1.5708 0" damping="0.2" />
                                                <geom pos="0 0 -0.03" type="mesh" mesh="LARM_MIDDLE1_LINK_mesh" />
                                            </body>
                                        </body>
                                    </body>
                                    <body name="LARM_RING3_LINK" pos="-0.00671263 -0.017 -0.100974">
                                        <inertial pos="0 0 0" quat="0.820473 0.339851 -0.17592 0.424708" mass="0.001" diaginertia="0.001 0.001 0.001" />
                                        <joint name="LARM_RING3_JOINT_R" pos="0 0 0" axis="0.996195 0 -0.0871557" limited="true" range="-1.5708 0" damping="0.2" />
                                        <geom pos="-0.00671263 -0.017 -0.100974" type="mesh" mesh="LARM_RING3_LINK_mesh" />
                                        <site name="via-forearm-6-4" pos="-0.00265825329193862 -0.00599999999999955 -0.030383797290909603" size="0.005"/>
                                        <site name="via-forearm-6-3" pos="-0.00100229417973312 -0.00599999999999955 -0.011456098027166399" size="0.005"/>
                                        <body name="LARM_RING2_LINK" pos="-0.00348623 0 -0.0398478">
                                            <inertial pos="0 0 0" quat="0.820473 0.339851 -0.17592 0.424708" mass="0.001" diaginertia="0.001 0.001 0.001" />
                                            <joint name="LARM_RING2_JOINT_R" pos="0 0 0" axis="0.996195 0 -0.0871557" limited="true" range="-1.5708 0" damping="0.2" />
                                            <geom pos="-0.00348623 0 -0.0398478" type="mesh" mesh="LARM_RING2_LINK_mesh" />
                                            <site name="via-forearm-6-6" pos="-0.00187385160720972 -0.00599999999999955 -0.0214180450080838" size="0.005"/>
                                            <site name="via-forearm-6-5" pos="-0.00108944992248079 -0.00599999999999955 -0.0124522927252581" size="0.005"/>
                                            <body name="LARM_RING1_LINK" pos="-0.00261467 0 -0.0298858">
                                                <inertial pos="0 0 0" quat="0.820473 0.339851 -0.17592 0.424708" mass="0.001" diaginertia="0.001 0.001 0.001" />
                                                <joint name="LARM_RING1_JOINT_R" pos="0 0 0" axis="0.996195 0 -0.0871557" limited="true" range="-1.5708 0" damping="0.2" />
                                                <geom pos="-0.00261467 0 -0.0298858" type="mesh" mesh="LARM_RING1_LINK_mesh" />
                                                <site name="pulled-forearm-6" pos="-0.00143807289347136 -0.01 -0.0164370715176251" size="0.005"/>
                                            </body>
                                        </body>
                                    </body>
                                    <body name="LARM_THUMB4_LINK" pos="0.0299678 -0.006 -0.0497134">
                                        <inertial pos="0 0 0" quat="0.820473 0.339851 -0.17592 0.424708" mass="0.001" diaginertia="0.001 0.001 0.001" />
                                        <joint name="LARM_THUMB4_JOINT_Y" pos="0 0 0" axis="-0.0871557 0 0.996195" limited="true" range="-2.09439 0" damping="0.2" />
                                        <geom pos="0.0299678 -0.006 -0.0497134" type="mesh" mesh="LARM_THUMB4_LINK_mesh" />
                                        <body name="LARM_THUMB3_LINK" pos="0 0 0">
                                            <inertial pos="0 0 0" quat="0.820473 0.339851 -0.17592 0.424708" mass="0.001" diaginertia="0.001 0.001 0.001" />
                                            <joint name="LARM_THUMB3_JOINT_Y" pos="0 0 0" axis="0 1 0" limited="true" range="0 0.872664" damping="0.2" />
                                            <geom type="mesh" mesh="LARM_THUMB3_LINK_mesh" />
                                            <site name="via-forearm-5-4" pos="0.019795545977449803 -0.0152426406871193 -0.00252699560313894" size="0.005"/>
                                            <site name="via-forearm-5-3" pos="0.010829793694624099 -0.0152426406871193 -0.00331139728786786" size="0.005"/>
                                            <site name="pulled-forearm-4" pos="0.0210322212855471 -0.0049618971736034604 -0.00128662650954127" size="0.005"/>
                                            <body name="LARM_THUMB2_LINK" pos="0.0360228 -0.011 -0.0109274">
                                                <inertial pos="0 0 0" quat="0.820473 0.339851 -0.17592 0.424708" mass="0.001" diaginertia="0.001 0.001 0.001" />
                                                <joint name="LARM_THUMB2_JOINT_Y" pos="0 0 0" axis="0.405582 -0.70711 0.579223" limited="true" range="-1.5708 0" damping="0.2" />
                                                <geom pos="0.0360228 -0.011 -0.0109274" type="mesh" mesh="LARM_THUMB2_LINK_mesh" />
                                                <site name="via-forearm-5-6" pos="0.0151743798552749 -0.004242655687119399 -0.0120525335003073" size="0.005"/>
                                                <site name="via-forearm-5-5" pos="0.00780201145667398 -0.004242655687119371 -0.00689034557314787" size="0.005"/>
                                                <body name="LARM_THUMB1_LINK" pos="0.0245746 0 -0.0172073">
                                                    <inertial pos="0 0 0" quat="0.820473 0.339851 -0.17592 0.424708" mass="0.001" diaginertia="0.001 0.001 0.001" />
                                                    <joint name="LARM_THUMB1_JOINT_Y" pos="0 0 0" axis="0.405582 -0.70711 0.579223" limited="true" range="-1.5708 0" damping="0.2" />
                                                    <geom pos="0.0245746 0 -0.0172073" type="mesh" mesh="LARM_THUMB1_LINK_mesh" />
                                                    <site name="pulled-forearm-5" pos="0.0104348212855471 -0.006000015 -0.0101519215095413" size="0.005"/>
                                                </body>
                                            </body>
                                        </body>
                                    </body>
                                </body>
                            </body>
                        </body>
                    </body>
                </body>
            </body>
        </body>

        <body name="g1" pos="0.334 0.3 -0.47" axisangle="0 1 0 0.05">
            <geom name="g1" rgba="0.2 0.2 0.2 1" type="box" size="0.003 0.01 0.05" contype="1" conaffinity="1" />
        </body>

        <body name="g2" pos="0.266 0.3 -0.47" axisangle="0 1 0 -0.05">
            <geom name="g2" rgba="0.2 0.2 0.2 1" type="box" size="0.003 0.01 0.05" contype="1" conaffinity="1" />
        </body>

        <body name="g3" pos="0.3 0.334 -0.47" axisangle="1 0 0 -0.05">
            <geom name="g3" rgba="0.2 0.2 0.2 1" type="box" size="0.01 0.003 0.05" contype="1" conaffinity="1" />
        </body>

        <body name="g4" pos="0.3 0.266 -0.47" axisangle="1 0 0 0.05">
            <geom name="g4" rgba="0.2 0.2 0.2 1" type="box" size="0.01 0.003 0.05" contype="1" conaffinity="1" />
        </body>

        <body name="fl" pos="0.3 0.3 -0.55">
            <geom name="fl" rgba="0.2 0.2 0.2 1" type="box" size="0.2 0.2 0.05" contype="1" conaffinity="1" />
        </body>

        <body name="w1" pos="0.516 0.3 -0.45">
            <geom name="w1" rgba="0.2 0.2 0.2 1" type="box" size="0.183 0.3 0.05" contype="1" conaffinity="1" />
        </body>

        <body name="w2" pos="0.084 0.3 -0.45">
            <geom name="w2" rgba="0.2 0.2 0.2 1" type="box" size="0.183 0.3 0.05" contype="1" conaffinity="1" />
        </body>

        <body name="w3" pos="0.3 0.516 -0.45">
            <geom name="w3" rgba="0.2 0.2 0.2 1" type="box" size="0.032 0.183 0.05" contype="1" conaffinity="1" />
        </body>
        
        <body name="w4" pos="0.3 0.084 -0.45">
            <geom name="w4" rgba="0.2 0.2 0.2 1" type="box" size="0.032 0.183 0.05" contype="1" conaffinity="1" />
        </body>

    </worldbody>
    <!--
    <tendon>
        <spatial name="wire-forearm-1l" width="0.003" rgba=".4 .6 .4 1">
            <site site="pull-forearm-1"/>
            <geom geom="LARM_HAND_DUMMY1_LINK"/>
            <site site="pulled-forearm-1"/>
        </spatial>
        <spatial name="wire-forearm-2l" width="0.003" rgba=".4 .6 .4 1">
            <site site="pull-forearm-2"/>
            <geom geom="LARM_HAND_DUMMY1_LINK"/>
            <site site="pulled-forearm-2"/>
        </spatial>
        <spatial name="wire-forearm-3l" width="0.003" rgba=".4 .6 .4 1">
            <site site="pull-forearm-3"/>
            <geom geom="LARM_HAND_DUMMY1_LINK"/>
            <site site="via-forearm-3-1"/>
            <site site="via-forearm-3-2"/>
            <site site="via-forearm-3-3"/>
            <site site="via-forearm-3-4"/>
            <site site="via-forearm-3-5"/>
            <site site="via-forearm-3-6"/>
            <site site="pulled-forearm-3"/>
        </spatial>
        <spatial name="wire-forearm-4l" width="0.003" rgba=".4 .6 .4 1">
            <site site="pull-forearm-4"/>
            <geom geom="LARM_HAND_DUMMY1_LINK"/>
            <site site="via-forearm-4-1"/>
            <site site="via-forearm-4-2"/>
            <site site="pulled-forearm-4"/>
        </spatial>
        <spatial name="wire-forearm-5l" width="0.003" rgba=".4 .6 .4 1">
            <site site="pull-forearm-5"/>
            <geom geom="LARM_HAND_DUMMY1_LINK"/>
            <site site="via-forearm-5-1"/>
            <site site="via-forearm-5-2"/>
            <site site="via-forearm-5-3"/>
            <site site="via-forearm-5-4"/>
            <site site="via-forearm-5-5"/>
            <site site="via-forearm-5-6"/>
            <site site="pulled-forearm-5"/>
        </spatial>
        <spatial name="wire-forearm-6l" width="0.003" rgba=".4 .6 .4 1">
            <site site="pull-forearm-6"/>
            <geom geom="LARM_HAND_DUMMY1_LINK"/>
            <site site="via-forearm-6-1"/>
            <site site="via-forearm-6-2"/>
            <site site="via-forearm-6-3"/>
            <site site="via-forearm-6-4"/>
            <site site="via-forearm-6-5"/>
            <site site="via-forearm-6-6"/>
            <site site="pulled-forearm-6"/>
        </spatial>
        <spatial name="wire-forearm-7l" width="0.003" rgba=".4 .6 .4 1">
            <site site="pull-forearm-7"/>
            <geom geom="LARM_HAND_DUMMY1_LINK"/>
            <site site="pulled-forearm-7"/>
        </spatial>
        <spatial name="wire-forearm-8l" width="0.003" rgba=".4 .6 .4 1">
            <site site="pull-forearm-8"/>
            <geom geom="LARM_HAND_DUMMY1_LINK"/>
            <site site="pulled-forearm-8"/>
        </spatial>
        <spatial name="wire-humerus-1l" width="0.005" rgba=".4 .6 .4 1">
            <site site="pull-humerus-1"/>
            <site site="via-humerus-1-1"/>
            <geom geom="LARM_FOREARM_DUMMY1_LINK"/>
            <site site="via-humerus-1-2"/>
            <geom geom="LARM_FOREARM_DUMMY1_LINK_cylinder_thin_thin" sidesite="larm-forearm-outer"/>
            <site site="via-humerus-1-3"/>
            <geom geom="LARM_FOREARM_DUMMY1_LINK_cylinder_thin_thin" sidesite="larm-forearm-outer"/>
            <site site="via-humerus-1-4"/>
            <geom geom="LARM_FOREARM_DUMMY1_LINK"/>
            <site site="via-humerus-1-5"/>
            <site site="pulled-humerus-1"/>
        </spatial>
        <spatial name="wire-humerus-2l" width="0.003" rgba=".4 .6 .4 1">
            <site site="pull-humerus-2"/>
            <geom geom="LARM_HUMERUS_DUMMY1_LINK"/>
            <site site="via-humerus-2-1"/>
            <geom geom="LARM_HUMERUS_DUMMY1_LINK"/>
            <site site="pulled-humerus-2"/>
        </spatial>
        <spatial name="wire-humerus-3l" width="0.003" rgba=".4 .6 .4 1">
            <site site="pull-humerus-3"/>
            <site site="via-humerus-3-1"/>
            <geom geom="LARM_FOREARM_DUMMY1_LINK"/>
            <site site="via-humerus-3-2"/>
            <geom geom="LARM_FOREARM_DUMMY1_LINK_cylinder_thin_thin" sidesite="larm-forearm-insider"/>
            <site site="via-humerus-3-3"/>
            <geom geom="LARM_FOREARM_DUMMY1_LINK_cylinder_thin_thin" sidesite="larm-forearm-insider"/>
            <site site="via-humerus-3-4"/>
            <geom geom="LARM_FOREARM_DUMMY1_LINK"/>
            <site site="via-humerus-3-5"/>
            <site site="pulled-humerus-3"/>
        </spatial>
        <spatial name="wire-humerus-4l" width="0.003" rgba=".4 .6 .4 1">
            <site site="pull-humerus-4"/>
            <geom geom="LARM_FOREARM_DUMMY1_LINK_cylinder_thin" sidesite="larm-forearm-front"/>
            <site site="via-humerus-4-1"/>
            <geom geom="LARM_FOREARM_DUMMY1_LINK_cylinder_thin" sidesite="larm-forearm-front"/>
            <site site="pulled-humerus-4"/>
        </spatial>
        <spatial name="wire-humerus-5l" width="0.003" rgba=".4 .6 .4 1">
            <site site="pull-humerus-5"/>
            <geom geom="LARM_FOREARM_DUMMY1_LINK_cylinder" sidesite="larm-forearm-front"/>
            <site site="via-humerus-5-1"/>
            <geom geom="LARM_FOREARM_DUMMY1_LINK_cylinder" sidesite="larm-forearm-front"/>
            <site site="pulled-humerus-5"/>
        </spatial>
        <spatial name="wire-scapula-1l" width="0.003" rgba=".4 .6 .4 1">
            <site site="pull-scapula-1"/>
            <site site="via-scapula-1-1"/>
            <geom geom="LARM_HUMERUS_DUMMY1_LINK"/>
            <site site="via-scapula-1-2"/>
        </spatial>
        <spatial name="wire-scapula-2l" width="0.003" rgba=".4 .6 .4 1">
            <site site="pull-scapula-2"/>
            <site site="via-scapula-2-1"/>
            <geom geom="LARM_HUMERUS_DUMMY1_LINK" sidesite="larm-humerus-linkouter"/>
            <site site="via-scapula-2-2"/>
            <geom geom="LARM_HUMERUS_DUMMY2_LINK" sidesite="larm-humerus-linkouter"/>
            <site site="pulled-scapula-2"/>
        </spatial>
        <spatial name="wire-scapula-3l" width="0.003" rgba=".4 .6 .4 1">
            <site site="pull-scapula-3"/>
            <site site="via-scapula-3-1"/>
            <geom geom="LARM_HUMERUS_DUMMY1_LINK"/>
            <site site="via-scapula-3-2"/>
            <geom geom="LARM_HUMERUS_DUMMY1_LINK" />
            <site site="pulled-scapula-3"/>
        </spatial>
        <spatial name="wire-scapula-4l" width="0.003" rgba=".4 .6 .4 1">
            <site site="pull-scapula-4"/>
            <geom geom="LARM_HUMERUS_DUMMY2_LINK_thin" sidesite="larm-humerus-linkinsider"/>
            <site site="via-scapula-4-1"/>
            <geom geom="LARM_HUMERUS_DUMMY2_LINK_thin"/>
            <site site="via-scapula-4-2"/>
            <geom geom="LARM_HUMERUS_DUMMY1_LINK"/>
            <site site="pulled-scapula-4"/>
        </spatial>
        <spatial name="wire-scapula-5l" width="0.003" rgba=".4 .6 .4 1">
            <site site="pull-scapula-5"/>
            <geom geom="LARM_HUMERUS_DUMMY2_LINK_thin"/>
            <site site="via-scapula-5-1"/>
            <geom geom="LARM_HUMERUS_DUMMY2_LINK_thin"/>
            <site site="via-scapula-5-2"/>
            <geom geom="LARM_HUMERUS_DUMMY1_LINK"/>
            <site site="pulled-scapula-5"/>
        </spatial>
    </tendon>
    -->
    <actuator>
        <!--
        <muscle name="wire-forearm-1l" tendon="wire-forearm-1l"/>
        <muscle name="wire-forearm-2l" tendon="wire-forearm-2l"/>
        <muscle name="wire-forearm-3l" tendon="wire-forearm-3l"/>
        <muscle name="wire-forearm-4l" tendon="wire-forearm-4l"/>
        <muscle name="wire-forearm-5l" tendon="wire-forearm-5l"/>
        <muscle name="wire-forearm-6l" tendon="wire-forearm-6l"/>
        <muscle name="wire-forearm-7l" tendon="wire-forearm-7l"/>
        <muscle name="wire-forearm-8l" tendon="wire-forearm-8l"/>
        <muscle name="wire-humerus-1l" tendon="wire-humerus-1l"/>
        <muscle name="wire-humerus-2l" tendon="wire-humerus-2l"/>
        <muscle name="wire-humerus-3l" tendon="wire-humerus-3l"/>
        <muscle name="wire-humerus-4l" tendon="wire-humerus-4l"/>
        <muscle name="wire-humerus-5l" tendon="wire-humerus-5l"/>
        <muscle name="wire-scapula-1l" tendon="wire-scapula-1l"/>
        <muscle name="wire-scapula-2l" tendon="wire-scapula-2l"/>
        <muscle name="wire-scapula-3l" tendon="wire-scapula-3l"/>
        <muscle name="wire-scapula-4l" tendon="wire-scapula-4l"/>
        <muscle name="wire-scapula-5l" tendon="wire-scapula-5l"/>
        -->
        <motor joint="LARM_SHOULDER_JOINT_P" ctrlrange="-100.0 100.0" ctrllimited="true"/>
        <motor joint="LARM_SHOULDER_JOINT_R" ctrlrange="-100.0 100.0" ctrllimited="true"/>
        <motor joint="LARM_SHOULDER_JOINT_Y" ctrlrange="-100.0 100.0" ctrllimited="true"/>
        <motor joint="LARM_ELBOW_JOINT_P" ctrlrange="-100.0 100.0" ctrllimited="true"/>
        <motor joint="LARM_ELBOW_JOINT_Y" ctrlrange="-100.0 100.0" ctrllimited="true"/>
        <motor joint="LARM_WRIST_JOINT_P" ctrlrange="-100.0 100.0" ctrllimited="true"/>
        <motor joint="LARM_WRIST_JOINT_R" ctrlrange="-100.0 100.0" ctrllimited="true"/>
    </actuator>
</mujoco>
